<sdf version='1.7'>
  <world name='default'>
    <light name='sun' type='directional'>
      <cast_shadows>1</cast_shadows>
      <pose>0 0 10 0 -0 0</pose>
      <diffuse>0.8 0.8 0.8 1</diffuse>
      <specular>0.2 0.2 0.2 1</specular>
      <attenuation>
        <range>1000</range>
        <constant>0.9</constant>
        <linear>0.01</linear>
        <quadratic>0.001</quadratic>
      </attenuation>
      <direction>-0.5 0.1 -0.9</direction>
      <spot>
        <inner_angle>0</inner_angle>
        <outer_angle>0</outer_angle>
        <falloff>0</falloff>
      </spot>
    </light>
    <model name='ground_plane'>
      <static>1</static>
      <link name='link'>
        <collision name='collision'>
          <geometry>
            <plane>
              <normal>0 0 1</normal>
              <size>100 100</size>
            </plane>
          </geometry>
          <surface>
            <friction>
              <ode>
                <mu>100</mu>
                <mu2>50</mu2>
              </ode>
              <torsional>
                <ode/>
              </torsional>
            </friction>
            <contact>
              <ode/>
            </contact>
            <bounce/>
          </surface>
          <max_contacts>10</max_contacts>
        </collision>
        <visual name='visual'>
          <cast_shadows>0</cast_shadows>
          <geometry>
            <plane>
              <normal>0 0 1</normal>
              <size>100 100</size>
            </plane>
          </geometry>
          <material>
            <script>
              <uri>file://media/materials/scripts/gazebo.material</uri>
              <name>Gazebo/Grey</name>
            </script>
          </material>
        </visual>
        <self_collide>0</self_collide>
        <enable_wind>0</enable_wind>
        <kinematic>0</kinematic>
      </link>
    </model>
    <gravity>0 0 -9.8</gravity>
    <magnetic_field>6e-06 2.3e-05 -4.2e-05</magnetic_field>
    <atmosphere type='adiabatic'/>
    <physics type='ode'>
      <max_step_size>0.001</max_step_size>
      <real_time_factor>1</real_time_factor>
      <real_time_update_rate>1000</real_time_update_rate>
    </physics>
    <scene>
      <ambient>0.4 0.4 0.4 1</ambient>
      <background>0.7 0.7 0.7 1</background>
      <shadows>1</shadows>
    </scene>
    <audio>
      <device>default</device>
    </audio>
    <wind/>
    <spherical_coordinates>
      <surface_model>EARTH_WGS84</surface_model>
      <latitude_deg>0</latitude_deg>
      <longitude_deg>0</longitude_deg>
      <elevation>0</elevation>
      <heading_deg>0</heading_deg>
    </spherical_coordinates>
    <model name='my_object'>
      <static>1</static>
      <link name='link'>
        <pose>0 0 0 0 -0 0</pose>
        <visual name='visual'>
          <geometry>
            <mesh>
              <uri>model://table/meshes/table.dae</uri>
              <scale>1 1 1</scale>
            </mesh>
          </geometry>
        </visual>
        <collision name='collision'>
          <geometry>
            <mesh>
              <uri>model://table/meshes/table.dae</uri>
              <scale>1 1 1</scale>
            </mesh>
          </geometry>
          <max_contacts>10</max_contacts>
          <surface>
            <contact>
              <ode/>
            </contact>
            <bounce/>
            <friction>
              <torsional>
                <ode/>
              </torsional>
              <ode/>
            </friction>
          </surface>
        </collision>
        <self_collide>0</self_collide>
        <enable_wind>0</enable_wind>
        <kinematic>0</kinematic>
      </link>
      <pose>1.15398 0.186864 0 0 -0 0</pose>
    </model>
    <state world_name='default'>
      <sim_time>195 475000000</sim_time>
      <real_time>4 479328336</real_time>
      <wall_time>1776761647 561065808</wall_time>
      <iterations>4416</iterations>
      <model name='gp7_sim_target_box'>
        <pose>0 -0.5 0.355 0 -0 0</pose>
        <scale>1 1 1</scale>
        <link name='box_link'>
          <pose>0 -0.5 0.355 0 -0 0</pose>
          <velocity>0 0 0 0 -0 0</velocity>
          <acceleration>0 0 0 0 -0 0</acceleration>
          <wrench>0 0 0 0 -0 0</wrench>
        </link>
      </model>
      <model name='gp7_yaskawa'>
        <pose>0 0 0 0 -0 0</pose>
        <scale>1 1 1</scale>
        <link name='base_link'>
          <pose>0 0 0 0 -0 0</pose>
          <velocity>0 0 1e-05 -1e-06 -7e-06 0</velocity>
          <acceleration>-0.001239 0.000117 0.020046 -0.001312 -0.014113 2.6e-05</acceleration>
          <wrench>-0.006623 0.000626 0.107122 0 -0 0</wrench>
        </link>
        <link name='link_b'>
          <pose>0.525555 -5.8e-05 0.758075 -1.57222 -1.45045 -3.1402</pose>
          <velocity>-0.00036 2e-06 -0.012477 3.9e-05 -0.027341 3e-06</velocity>
          <acceleration>-0.430478 0.002794 -11.9524 0.013949 -1.37774 0.005217</acceleration>
          <wrench>-0.163666 0.001062 -4.54426 0 -0 0</wrench>
        </link>
        <link name='link_l'>
          <pose>0.04033 -0.000833 0.330233 -1.5702 -1.56947 3.141</pose>
          <velocity>3e-06 -1e-06 9e-06 9e-06 0.000133 1.5e-05</velocity>
          <acceleration>0.025061 -0.00295 0.020172 0.015338 0.157351 0.044328</acceleration>
          <wrench>0.172165 -0.020266 0.138583 0 -0 0</wrench>
        </link>
        <link name='link_r'>
          <pose>0.159914 -6e-05 0.803883 -3.14022 -1.4462 -0.001382</pose>
          <velocity>0.000939 -4e-06 -0.002108 4e-05 0.02836 1.2e-05</velocity>
          <acceleration>0.329077 -0.00055 -6.91353 -2.92418 -0.078809 3.10939</acceleration>
          <wrench>1.01435 -0.001697 -21.3103 0 -0 0</wrench>
        </link>
        <link name='link_s'>
          <pose>0 0 0.149 0 0 -2e-06</pose>
          <velocity>2e-06 -1e-06 1e-05 3e-06 2e-06 1.4e-05</velocity>
          <acceleration>0.000135 -0.001211 0.019717 0.002345 -0.004927 0.014143</acceleration>
          <wrench>0.000484 -0.004347 0.070747 0 -0 0</wrench>
        </link>
        <link name='link_t'>
          <pose>0.684954 -6.5e-05 0.776849 -0.000552 -1.45045 -3.14107</pose>
          <velocity>-0.000873 2e-06 -0.008119 1.8e-05 -0.027341 -1e-06</velocity>
          <acceleration>-0.682267 0.002562 -9.78321 -3.12173 -0.926717 -3.12681</acceleration>
          <wrench>-0.072134 0.000271 -1.03435 0 -0 0</wrench>
        </link>
        <link name='link_u'>
          <pose>0.08549 -0.001482 0.772936 1.57079 -1.4462 8e-06</pose>
          <velocity>6.2e-05 -5e-06 3e-06 9e-06 0.028359 1.5e-05</velocity>
          <acceleration>0.681245 -0.004802 0.527139 -1.50823 -1.50674 -1.87932</acceleration>
          <wrench>1.83988 -0.012968 1.42368 0 -0 0</wrench>
        </link>
      </model>
      <model name='ground_plane'>
        <pose>0 0 0 0 -0 0</pose>
        <scale>1 1 1</scale>
        <link name='link'>
          <pose>0 0 0 0 -0 0</pose>
          <velocity>0 0 0 0 -0 0</velocity>
          <acceleration>0 0 0 0 -0 0</acceleration>
          <wrench>0 0 0 0 -0 0</wrench>
        </link>
      </model>
      <model name='my_object'>
        <pose>0 -0.5 0 0 -0 0</pose>
        <scale>1 1 1</scale>
        <link name='link'>
          <pose>0 -0.5 0 0 -0 0</pose>
          <velocity>0 0 0 0 -0 0</velocity>
          <acceleration>0 0 0 0 -0 0</acceleration>
          <wrench>0 0 0 0 -0 0</wrench>
        </link>
      </model>
      <light name='sun'>
        <pose>0 0 10 0 -0 0</pose>
      </light>
    </state>
    <gui fullscreen='0'>
      <camera name='user_camera'>
        <pose>-1.90298 0.688825 1.47107 -0 0.411267 -0.593139</pose>
        <view_controller>orbit</view_controller>
        <projection_type>perspective</projection_type>
      </camera>
    </gui>
    <model name='gp7_sim_target_box'>
      <static>1</static>
      <link name='box_link'>
        <pose>0 0 0 0 -0 0</pose>
        <visual name='box_visual'>
          <geometry>
            <box>
              <size>0.1 0.05 0.05</size>
            </box>
          </geometry>
          <material>
            <ambient>0.2 0.7 0.2 1</ambient>
            <diffuse>0.2 0.9 0.2 1</diffuse>
            <specular>0.2 0.2 0.2 1</specular>
          </material>
        </visual>
        <collision name='box_collision'>
          <geometry>
            <box>
              <size>0.1 0.05 0.05</size>
            </box>
          </geometry>
          <max_contacts>10</max_contacts>
          <surface>
            <contact>
              <ode/>
            </contact>
            <bounce/>
            <friction>
              <torsional>
                <ode/>
              </torsional>
              <ode/>
            </friction>
          </surface>
        </collision>
        <self_collide>0</self_collide>
        <enable_wind>0</enable_wind>
        <kinematic>0</kinematic>
      </link>
      <pose>0 -0.7 0.025 0 -0 0</pose>
    </model>
    <model name='gp7_yaskawa'>
      <joint name='world_to_base' type='fixed'>
        <pose relative_to='__model__'>0 0 0 0 -0 0</pose>
        <parent>world</parent>
        <child>base_link</child>
      </joint>
      <link name='base_link'>
        <pose relative_to='world_to_base'>0 0 0 0 -0 0</pose>
        <inertial>
          <pose>-0.006249 -4.1e-05 0.087896 0 -0 0</pose>
          <mass>5.34386</mass>
          <inertia>
            <ixx>0.0268121</ixx>
            <ixy>-5.49304e-06</ixy>
            <ixz>-6.58205e-05</ixz>
            <iyy>0.029881</iyy>
            <iyz>-1.07584e-05</iyz>
            <izz>0.0280953</izz>
          </inertia>
        </inertial>
        <collision name='base_link_collision'>
          <pose>0 0 0 0 -0 0</pose>
          <geometry>
            <mesh>
              <scale>1 1 1</scale>
              <uri>model://gp7_description/meshes/base_link.STL</uri>
            </mesh>
          </geometry>
          <surface>
            <contact>
              <ode/>
            </contact>
            <friction>
              <ode/>
              <torsional>
                <ode/>
              </torsional>
            </friction>
            <bounce/>
          </surface>
          <max_contacts>10</max_contacts>
        </collision>
        <visual name='base_link_visual'>
          <pose>0 0 0 0 -0 0</pose>
          <geometry>
            <mesh>
              <scale>1 1 1</scale>
              <uri>model://gp7_description/meshes/base_link.STL</uri>
            </mesh>
          </geometry>
          <material>
            <script>
              <name>Gazebo/Blue</name>
              <uri>file://media/materials/scripts/gazebo.material</uri>
            </script>
          </material>
        </visual>
        <self_collide>0</self_collide>
        <enable_wind>0</enable_wind>
        <kinematic>0</kinematic>
      </link>
      <joint name='joint_s' type='revolute'>
        <pose relative_to='base_link'>0 0 0.149 0 -0 0</pose>
        <parent>base_link</parent>
        <child>link_s</child>
        <axis>
          <xyz>0 0 1</xyz>
          <limit>
            <lower>-2.97</lower>
            <upper>2.97</upper>
            <effort>100</effort>
            <velocity>100</velocity>
          </limit>
          <dynamics>
            <spring_reference>0</spring_reference>
            <spring_stiffness>0</spring_stiffness>
          </dynamics>
        </axis>
      </joint>
      <link name='link_s'>
        <pose relative_to='joint_s'>0 0 0 0 -0 0</pose>
        <inertial>
          <pose>0.011859 -0.002953 0.12221 0 -0 0</pose>
          <mass>3.58813</mass>
          <inertia>
            <ixx>0.0176546</ixx>
            <ixy>0.000292412</ixy>
            <ixz>-0.00271185</ixz>
            <iyy>0.0196884</iyy>
            <iyz>0.000611148</iyz>
            <izz>0.0110073</izz>
          </inertia>
        </inertial>
        <collision name='link_s_collision'>
          <pose>0 0 0 0 -0 0</pose>
          <geometry>
            <mesh>
              <scale>1 1 1</scale>
              <uri>model://gp7_description/meshes/link_s.STL</uri>
            </mesh>
          </geometry>
          <surface>
            <contact>
              <ode/>
            </contact>
            <friction>
              <ode/>
              <torsional>
                <ode/>
              </torsional>
            </friction>
            <bounce/>
          </surface>
          <max_contacts>10</max_contacts>
        </collision>
        <visual name='link_s_visual'>
          <pose>0 0 0 0 -0 0</pose>
          <geometry>
            <mesh>
              <scale>1 1 1</scale>
              <uri>model://gp7_description/meshes/link_s.STL</uri>
            </mesh>
          </geometry>
          <material>
            <script>
              <name>Gazebo/White</name>
              <uri>file://media/materials/scripts/gazebo.material</uri>
            </script>
          </material>
        </visual>
        <self_collide>0</self_collide>
        <enable_wind>0</enable_wind>
        <kinematic>0</kinematic>
      </link>
      <joint name='joint_l' type='revolute'>
        <pose relative_to='link_s'>0.04033 -0.000833 0.181233 -1.57079 -1.57079 3.14159</pose>
        <parent>link_s</parent>
        <child>link_l</child>
        <axis>
          <xyz>0 0 -1</xyz>
          <limit>
            <lower>-1.13</lower>
            <upper>2.53</upper>
            <effort>100</effort>
            <velocity>100</velocity>
          </limit>
          <dynamics>
            <spring_reference>0</spring_reference>
            <spring_stiffness>0</spring_stiffness>
          </dynamics>
        </axis>
      </joint>
      <link name='link_l'>
        <pose relative_to='joint_l'>0 0 0 0 -0 0</pose>
        <inertial>
          <pose>0.195096 0.005887 -0.003585 0 -0 0</pose>
          <mass>6.86997</mass>
          <inertia>
            <ixx>0.049355</ixx>
            <ixy>0.0124405</ixy>
            <ixz>-9.21313e-05</ixz>
            <iyy>0.169029</iyy>
            <iyz>-0.000474993</iyz>
            <izz>0.135763</izz>
          </inertia>
        </inertial>
        <collision name='link_l_collision'>
          <pose>0 0 0 0 -0 0</pose>
          <geometry>
            <mesh>
              <scale>1 1 1</scale>
              <uri>model://gp7_description/meshes/link_l.STL</uri>
            </mesh>
          </geometry>
          <surface>
            <contact>
              <ode/>
            </contact>
            <friction>
              <ode/>
              <torsional>
                <ode/>
              </torsional>
            </friction>
            <bounce/>
          </surface>
          <max_contacts>10</max_contacts>
        </collision>
        <visual name='link_l_visual'>
          <pose>0 0 0 0 -0 0</pose>
          <geometry>
            <mesh>
              <scale>1 1 1</scale>
              <uri>model://gp7_description/meshes/link_l.STL</uri>
            </mesh>
          </geometry>
          <material>
            <script>
              <name>Gazebo/Blue</name>
              <uri>file://media/materials/scripts/gazebo.material</uri>
            </script>
          </material>
        </visual>
        <self_collide>0</self_collide>
        <enable_wind>0</enable_wind>
        <kinematic>0</kinematic>
      </link>
      <joint name='joint_u' type='revolute'>
        <pose relative_to='link_l'>0.442643 -0.045747 0.00065 0 -0 0</pose>
        <parent>link_l</parent>
        <child>link_u</child>
        <axis>
          <xyz>0 0 1</xyz>
          <limit>
            <lower>-1.22</lower>
            <upper>3.32</upper>
            <effort>100</effort>
            <velocity>100</velocity>
          </limit>
          <dynamics>
            <spring_reference>0</spring_reference>
            <spring_stiffness>0</spring_stiffness>
          </dynamics>
        </axis>
      </joint>
      <link name='link_u'>
        <pose relative_to='joint_u'>0 0 0 0 -0 0</pose>
        <inertial>
          <pose>0.019627 0.020712 0.001558 0 -0 0</pose>
          <mass>2.70076</mass>
          <inertia>
            <ixx>0.00868308</ixx>
            <ixy>0.00058566</ixy>
            <ixz>0.000160022</ixz>
            <iyy>0.00807038</iyy>
            <iyz>0.000206152</iyz>
            <izz>0.00973495</izz>
          </inertia>
        </inertial>
        <collision name='link_u_collision'>
          <pose>0 0 0 0 -0 0</pose>
          <geometry>
            <mesh>
              <scale>1 1 1</scale>
              <uri>model://gp7_description/meshes/link_u.STL</uri>
            </mesh>
          </geometry>
          <surface>
            <contact>
              <ode/>
            </contact>
            <friction>
              <ode/>
              <torsional>
                <ode/>
              </torsional>
            </friction>
            <bounce/>
          </surface>
          <max_contacts>10</max_contacts>
        </collision>
        <visual name='link_u_visual'>
          <pose>0 0 0 0 -0 0</pose>
          <geometry>
            <mesh>
              <scale>1 1 1</scale>
              <uri>model://gp7_description/meshes/link_u.STL</uri>
            </mesh>
          </geometry>
          <material>
            <script>
              <name>Gazebo/White</name>
              <uri>file://media/materials/scripts/gazebo.material</uri>
            </script>
          </material>
        </visual>
        <self_collide>0</self_collide>
        <enable_wind>0</enable_wind>
        <kinematic>0</kinematic>
      </link>
      <joint name='joint_r' type='revolute'>
        <pose relative_to='link_u'>0.039956 -0.070001 -0.001422 1.5708 -0 0</pose>
        <parent>link_u</parent>
        <child>link_r</child>
        <axis>
          <xyz>3.5e-05 0 -1</xyz>
          <limit>
            <lower>-3.32</lower>
            <upper>3.32</upper>
            <effort>17</effort>
            <velocity>100</velocity>
          </limit>
          <dynamics>
            <spring_reference>0</spring_reference>
            <spring_stiffness>0</spring_stiffness>
          </dynamics>
        </axis>
      </joint>
      <link name='link_r'>
        <pose relative_to='joint_r'>0 0 0 0 -0 0</pose>
        <inertial>
          <pose>-3.8e-05 6.6e-05 0.171222 0 -0 0</pose>
          <mass>3.08241</mass>
          <inertia>
            <ixx>0.0351496</ixx>
            <ixy>6.47179e-07</ixy>
            <ixz>1.44147e-06</ixz>
            <iyy>0.0345408</iyy>
            <iyz>-1.51647e-05</iyz>
            <izz>0.00466894</izz>
          </inertia>
        </inertial>
        <collision name='link_r_collision'>
          <pose>0 0 0 0 -0 0</pose>
          <geometry>
            <mesh>
              <scale>1 1 1</scale>
              <uri>model://gp7_description/meshes/link_r.STL</uri>
            </mesh>
          </geometry>
          <surface>
            <contact>
              <ode/>
            </contact>
            <friction>
              <ode/>
              <torsional>
                <ode/>
              </torsional>
            </friction>
            <bounce/>
          </surface>
          <max_contacts>10</max_contacts>
        </collision>
        <visual name='link_r_visual'>
          <pose>0 0 0 0 -0 0</pose>
          <geometry>
            <mesh>
              <scale>1 1 1</scale>
              <uri>model://gp7_description/meshes/link_r.STL</uri>
            </mesh>
          </geometry>
          <material>
            <script>
              <name>Gazebo/Blue</name>
              <uri>file://media/materials/scripts/gazebo.material</uri>
            </script>
          </material>
        </visual>
        <self_collide>0</self_collide>
        <enable_wind>0</enable_wind>
        <kinematic>0</kinematic>
      </link>
      <joint name='joint_b' type='revolute'>
        <pose relative_to='link_r'>-1.3e-05 0 0.3685 -1.5708 0 0</pose>
        <parent>link_r</parent>
        <child>link_b</child>
        <axis>
          <xyz>0 0 1</xyz>
          <limit>
            <lower>-2.36</lower>
            <upper>2.36</upper>
            <effort>17</effort>
            <velocity>100</velocity>
          </limit>
          <dynamics>
            <spring_reference>0</spring_reference>
            <spring_stiffness>0</spring_stiffness>
          </dynamics>
        </axis>
      </joint>
      <link name='link_b'>
        <pose relative_to='joint_b'>0 0 0 0 -0 0</pose>
        <inertial>
          <pose>0.000121 -0.018846 -1.6e-05 0 -0 0</pose>
          <mass>0.380195</mass>
          <inertia>
            <ixx>0.00044843</ixx>
            <ixy>5.90645e-07</ixy>
            <ixz>-4.00837e-07</ixz>
            <iyy>0.000244637</iyy>
            <iyz>1.94113e-07</iyz>
            <izz>0.000479793</izz>
          </inertia>
        </inertial>
        <collision name='link_b_collision'>
          <pose>0 0 0 0 -0 0</pose>
          <geometry>
            <mesh>
              <scale>1 1 1</scale>
              <uri>model://gp7_description/meshes/link_b.STL</uri>
            </mesh>
          </geometry>
          <surface>
            <contact>
              <ode/>
            </contact>
            <friction>
              <ode/>
              <torsional>
                <ode/>
              </torsional>
            </friction>
            <bounce/>
          </surface>
          <max_contacts>10</max_contacts>
        </collision>
        <visual name='link_b_visual'>
          <pose>0 0 0 0 -0 0</pose>
          <geometry>
            <mesh>
              <scale>1 1 1</scale>
              <uri>model://gp7_description/meshes/link_b.STL</uri>
            </mesh>
          </geometry>
          <material>
            <script>
              <name>Gazebo/White</name>
              <uri>file://media/materials/scripts/gazebo.material</uri>
            </script>
          </material>
        </visual>
        <self_collide>0</self_collide>
        <enable_wind>0</enable_wind>
        <kinematic>0</kinematic>
      </link>
      <joint name='joint_t' type='revolute'>
        <pose relative_to='link_b'>-0.000498 -0.1605 0 1.5708 -0 0</pose>
        <parent>link_b</parent>
        <child>link_t</child>
        <axis>
          <xyz>-0.0031 0 -1</xyz>
          <limit>
            <lower>-6.28</lower>
            <upper>6.28</upper>
            <effort>10</effort>
            <velocity>100</velocity>
          </limit>
          <dynamics>
            <spring_reference>0</spring_reference>
            <spring_stiffness>0</spring_stiffness>
          </dynamics>
        </axis>
      </joint>
      <link name='link_t'>
        <pose relative_to='joint_t'>0 0 0 0 -0 0</pose>
        <inertial>
          <pose>0.000235 2.3e-05 -0.061804 0 -0 0</pose>
          <mass>0.105727</mass>
          <inertia>
            <ixx>2.85659e-05</ixx>
            <ixy>8.25842e-10</ixy>
            <ixz>-9.14025e-08</ixz>
            <iyy>2.84622e-05</iyy>
            <iyz>-1.72938e-08</iyz>
            <izz>4.56469e-05</izz>
          </inertia>
        </inertial>
        <collision name='link_t_collision'>
          <pose>0 0 0 0 -0 0</pose>
          <geometry>
            <mesh>
              <scale>1 1 1</scale>
              <uri>model://gp7_description/meshes/link_t.STL</uri>
            </mesh>
          </geometry>
          <surface>
            <contact>
              <ode/>
            </contact>
            <friction>
              <ode/>
              <torsional>
                <ode/>
              </torsional>
            </friction>
            <bounce/>
          </surface>
          <max_contacts>10</max_contacts>
        </collision>
        <visual name='link_t_visual'>
          <pose>0 0 0 0 -0 0</pose>
          <geometry>
            <mesh>
              <scale>1 1 1</scale>
              <uri>model://gp7_description/meshes/link_t.STL</uri>
            </mesh>
          </geometry>
          <material>
            <script>
              <name>Gazebo/Blue</name>
              <uri>file://media/materials/scripts/gazebo.material</uri>
            </script>
          </material>
        </visual>
        <self_collide>0</self_collide>
        <enable_wind>0</enable_wind>
        <kinematic>0</kinematic>
      </link>
      <static>0</static>
      <plugin name='gazebo_ros2_control' filename='libgazebo_ros2_control.so'>
        <parameters>/home/norman/pap_yaskawa_ws/install/gp7_bringup/share/gp7_bringup/config/gp7_controller.yaml</parameters>
      </plugin>
      <pose>0 0 0 0 -0 0</pose>
    </model>
  </world>
</sdf>
